<?xml version="1.0"?>
<robot name="materials">

  <material name="blue">
    <color rgba="0 0 0.8 1"/>
  </material>

  <material name="white">
    <color rgba="1 1 1 1"/>
  </material>
  
  <material name="black">
    <color rgba="0 0 0 1"/>
  </material>

  <link name="base_link">
    <visual>
      <geometry>
        <cylinder length="1.0" radius="0.4"/>
      </geometry>
      <!-- [오타 수정] 순수 URDF는 글자 pi/2를 연산하지 못하므로 숫자로 변경 (pi/2 -> 1.570796) -->
      <origin xyz="0 0 0.1" rpy="0 1.570796 0"/>
      <material name="white"/>
    </visual>
    <inertial>
      <mass value="10"/>
      <inertia ixx="1e-3" ixy="0.0" ixz="0.0" iyy="1e-3" iyz="0.0" izz="1e-3"/>
    </inertial>
  </link>
    
  <link name="right_wheel">
    <visual>
      <geometry>
        <cylinder length="0.1" radius="0.5"/>
      </geometry>
      <!-- [오타 수정] 글자 pi/2를 숫자로 변경 (pi/2 -> 1.570796) -->
      <origin xyz="0 0 0" rpy="0 0 0"/>
      <material name="black"/>
    </visual>
    <inertial>
      <mass value="1"/>
      <inertia ixx="1e-3" ixy="0.0" ixz="0.0" iyy="1e-3" iyz="0.0" izz="1e-3"/>
    </inertial>
  </link>

  <link name="left_wheel">
    <visual>
      <geometry>
        <cylinder length="0.1" radius="0.5"/>
      </geometry>
      <!-- [오타 수정] 글자 -pi/2를 숫자로 변경 (-pi/2 -> -1.570796) -->
      <origin xyz="0 0 0" rpy="0 0 0"/>
      <material name="black"/>
    </visual>
    <inertial>
      <mass value="1"/>
      <inertia ixx="1e-3" ixy="0.0" ixz="0.0" iyy="1e-3" iyz="0.0" izz="1e-3"/>
    </inertial>
  </link>

  <joint name="right_wheel_joint" type="continuous">
    <parent link="base_link"/>
    <child link="right_wheel"/>
    <!-- [오타 수정] 글자 pi/2를 숫자로 변경 (pi/2 -> 1.570796) -->
    <origin xyz="0 0.5 0" rpy="1.570796 0 0"/>
    <axis xyz="0 0 1"/>
  </joint>

  <joint name="left_wheel_joint" type="continuous">
    <parent link="base_link"/>
    <child link="left_wheel"/>
    <!-- [오타 수정] 글자 -pi/2를 숫자로 변경 (-pi/2 -> -1.570796) -->
    <origin xyz="0 -0.5 0" rpy="-1.570796 0 0"/>
    <axis xyz="0 0 -1"/>
  </joint>
</robot>
